Failure # 1 (occurred at 2025-01-25_18-28-30)
[36mray::ImplicitFunc.train()[39m (pid=9688, ip=172.24.13.56, actor_id=be80df3097c6344fd0cf9dee01000000, repr=train)
           ^^^^^^^^^^^^^^^^^^^^^^^^^^^^^^^^^^^^
           ^^^^^^^^^^^^^^^^^^^^^^^^^^^^^^^
  File "/home/digvijay/Documents/developer/greedy_kernel_alignment/kgreedy/lib/python3.12/site-packages/ray/tune/trainable/trainable.py", line 331, in train
    raise skipped from exception_cause(skipped)
  File "/home/digvijay/Documents/developer/greedy_kernel_alignment/kgreedy/lib/python3.12/site-packages/ray/air/_internal/util.py", line 104, in run
    self._ret = self._target(*self._args, **self._kwargs)
                ^^^^^^^^^^^^^^^^^^^^^^^^^^^^^^^^^^^^^^^^^
  File "/home/digvijay/Documents/developer/greedy_kernel_alignment/kgreedy/lib/python3.12/site-packages/ray/tune/trainable/function_trainable.py", line 45, in <lambda>
    training_func=lambda: self._trainable_func(self.config),
                          ^^^^^^^^^^^^^^^^^^^^^^^^^^^^^^^^^
           ^^^^^^^^^^^^^^^^^^^^^^^^^^^^^^^
  File "/home/digvijay/Documents/developer/greedy_kernel_alignment/kgreedy/lib/python3.12/site-packages/ray/tune/trainable/function_trainable.py", line 250, in _trainable_func
    output = fn()
             ^^^^
  File "/home/digvijay/Documents/developer/greedy_kernel_alignment/main.py", line 41, in train
    features, target = data_generator.generate_dataset()
                       ^^^^^^^^^^^^^^^^^^^^^^^^^^^^^^^^^
  File "/home/digvijay/Documents/developer/greedy_kernel_alignment/utils/data_generator.py", line 29, in generate_dataset
    return self.load_from_file()
           ^^^^^^^^^^^^^^^^^^^^^
  File "/home/digvijay/Documents/developer/greedy_kernel_alignment/utils/data_generator.py", line 109, in load_from_file
    x_train, x_test = data['x_train'], data['x_test']
                      ~~~~^^^^^^^^^^^
KeyError: 'x_train'
