Failure # 1 (occurred at 2024-11-04_19-13-04)
[36mray::ImplicitFunc.train()[39m (pid=85642, ip=172.24.11.109, actor_id=9db97b138cdbade7c326e70e01000000, repr=train)
           ^^^^^^^^^^^^^^^^^^^^^^^^^^^^^^^^^^^^
           ^^^^^^^^^^^^^^^^^^^^^^^^^^^^^^^
  File "/home/digvijay/Documents/developer/greedy_kernel_alignment/kgreedy/lib/python3.12/site-packages/ray/tune/trainable/trainable.py", line 331, in train
    raise skipped from exception_cause(skipped)
  File "/home/digvijay/Documents/developer/greedy_kernel_alignment/kgreedy/lib/python3.12/site-packages/ray/air/_internal/util.py", line 104, in run
    self._ret = self._target(*self._args, **self._kwargs)
                ^^^^^^^^^^^^^^^^^^^^^^^^^^^^^^^^^^^^^^^^^
  File "/home/digvijay/Documents/developer/greedy_kernel_alignment/kgreedy/lib/python3.12/site-packages/ray/tune/trainable/function_trainable.py", line 45, in <lambda>
    training_func=lambda: self._trainable_func(self.config),
                          ^^^^^^^^^^^^^^^^^^^^^^^^^^^^^^^^^
           ^^^^^^^^^^^^^^^^^^^^^^^^^^^^^^^
  File "/home/digvijay/Documents/developer/greedy_kernel_alignment/kgreedy/lib/python3.12/site-packages/ray/tune/trainable/function_trainable.py", line 250, in _trainable_func
    output = fn()
             ^^^^
  File "/home/digvijay/Documents/developer/greedy_kernel_alignment/kgreedy/lib/python3.12/site-packages/ray/tune/trainable/util.py", line 130, in inner
    return trainable(config, **fn_kwargs)
           ^^^^^^^^^^^^^^^^^^^^^^^^^^^^^^
  File "/home/digvijay/Documents/developer/greedy_kernel_alignment/main.py", line 78, in train
    agent.fit_kernel(training_data, training_labels)
  File "/home/digvijay/Documents/developer/greedy_kernel_alignment/utils/agent.py", line 168, in fit_kernel
    sampled_data, sampled_labels = samples_func(training_data, training_labels)
                                   ^^^^^^^^^^^^^^^^^^^^^^^^^^^^^^^^^^^^^^^^^^^^
TypeError: 'Tensor' object is not callable
