Failure # 1 (occurred at 2024-11-07_17-56-48)
[36mray::ImplicitFunc.train()[39m (pid=15844, ip=172.24.11.109, actor_id=cf19aa84331ea640d86dad8801000000, repr=train)
           ^^^^^^^^^^^^^^^^^^^^^^^^^^^^^^^^^^^^
           ^^^^^^^^^^^^^^^^^^^^^^^^^^^^^^^
  File "/home/digvijay/Documents/developer/greedy_kernel_alignment/kgreedy/lib/python3.12/site-packages/ray/tune/trainable/trainable.py", line 331, in train
    raise skipped from exception_cause(skipped)
  File "/home/digvijay/Documents/developer/greedy_kernel_alignment/kgreedy/lib/python3.12/site-packages/ray/air/_internal/util.py", line 104, in run
    self._ret = self._target(*self._args, **self._kwargs)
                ^^^^^^^^^^^^^^^^^^^^^^^^^^^^^^^^^^^^^^^^^
  File "/home/digvijay/Documents/developer/greedy_kernel_alignment/kgreedy/lib/python3.12/site-packages/ray/tune/trainable/function_trainable.py", line 45, in <lambda>
    training_func=lambda: self._trainable_func(self.config),
                          ^^^^^^^^^^^^^^^^^^^^^^^^^^^^^^^^^
           ^^^^^^^^^^^^^^^^^^^^^^^^^^^^^^^
  File "/home/digvijay/Documents/developer/greedy_kernel_alignment/kgreedy/lib/python3.12/site-packages/ray/tune/trainable/function_trainable.py", line 250, in _trainable_func
    output = fn()
             ^^^^
  File "/home/digvijay/Documents/developer/greedy_kernel_alignment/kgreedy/lib/python3.12/site-packages/ray/tune/trainable/util.py", line 130, in inner
    return trainable(config, **fn_kwargs)
           ^^^^^^^^^^^^^^^^^^^^^^^^^^^^^^
  File "/home/digvijay/Documents/developer/greedy_kernel_alignment/main.py", line 86, in train
    tune.report(accuracy=after_metrics['accuracy'], final_data = results)
    ^^^^^^^^^^^
AttributeError: module 'ray.tune' has no attribute 'report'
